Workbook

Sheet はじめにご確認ください）記入にあたっての留意事項
A1: 研究計画調書の記載にあたっての留意事項
B3: No | C3: 項目 | D3: 留意事項
B4: 1 | C4: 入力内容の確認について | D4: 未入力のセルは薄いオレンジ色で表示されています。提出前に、記入が必要な箇所について、薄いオレンジのセルが解消されているか必ず確認してください。 ※薄いオレンジ色のセルは未入力箇所を示していますが、すべての項目が記入必須ではありません。該当しない項目や入力不要な項目については、無理に記入する必要はありません。
B5: 2 | C5: 文字数制限の確認について | D5: 文字数制限のある項目は、文字数カウントを必ず確認のうえ、既定の文字数範囲内に収めてください。 文字数制限に対して超過/不足している場合、書類不備として「不受理」扱いとなることがございますので、ご留意ください。 ★上限超過または下限不足の場合、文字数カウントが赤字で表示されます
B6: 3 | C6: 調書の構成について | D6: 研究計画調書の構成は下記のとおりです。応募者による記入が必要なタブは、全体で4枚となっております。 ・はじめにご確認ください）記入にあたっての留意事項 ・参考）府省共通経費取扱区分表 ・研究計画調書_1枚目：基本情報 ・研究計画調書_2枚目：研究目的、研究方法等 ・研究計画調書_3枚目：研究経費の内訳 ・研究計画調書_4枚目：API・計算資源の算定根拠の詳細 ※必要な場合のみ記入
B7: 4 | C7: 様式（フォーマット）の取扱いについて | D7: 調書は入力項目以外の編集が、原則制限されています。必要な場合を除いて、レイアウト・書式の変更は行わないでください。
B8: 5 | C8: 研究計画調書のファイル名について | D8: 本ファイルのファイル名「様式１＿第2回研究計画調書＿e-Rad所属機関コード＿ローマ字氏名」のうち、「e-Rad所属機関コード」「ローマ字氏名」をご自身の情報に更新ください。e-Rad所属機関コードは半角数字、ローマ字氏名は半角英字で姓名の順で記載いただき、姓名の間には半角でスペースを空けてください。
B9: 6 | C9: 研究経費について | D9: 研究計画調書1枚目の「研究経費」の「総計」欄について、研究経費の総計が、10万円未満または500万円を超える場合には赤くエラー表示がされます。 金額を記載の際には、必ず半角数字とし、千円未満の端数は切り捨ててください。
B10: 7 | C10: その他 | D10: 研究領域およびユースケースの定義については、下記に提示する情報を参照のうえ、ご自身の該当のものを選択してください。 また研究経費については、下部の「府省共通経費取扱区分表について」および別タブの「参考）府省共通経費取扱区分表」を参照しご記載ください。
A12: 【参考：研究領域分類】
B14: 研究領域 | C14: 定義 | E14: 研究分野（例）
B15: 臨床科学 | C15: 疾患の診断・治療・予防・予後改善を目的に、患者・集団・医療現場を対象として知見を創出・検証する研究領域。 | E15: 内科医学、臓器別内科・生体情報医学、外科医学、機能・感覚系外科、口腔科学、社会医学・看護学、スポーツ科学、獣医学 等
B16: 生命科学・薬学 | C16: 生命現象を分子・細胞・個体レベルで解明し、創薬・薬理・生体制御へ展開する研究領域。 | E16: 細胞生物学、進化生物学、神経科学、薬学、生体構造・機能学、病理学、腫瘍学、脳科学 等
B17: 化学 | C17: 原子・分子・物質の構造、反応、物性、合成、変換を扱い、新物質・新機能を創出する研究領域。 | E17: 物理化学、有機化学、無機・錯体・分析化学、高分子・有機材料額、無機材料・エネルギー化学、生体分子化学 等
B18: 機械・社会基盤・エネルギー工学 | C18: 機械、構造、流体・熱、移動体、建築・土木、社会基盤、安全・防災、エネルギーシステムを対象に、設計・制御・実装を行う研究領域。 | E18: 材料力学・設計・生産工学、流体・熱工学、機械力学・ロボティクス、土木工学、建築学、航空宇宙・海洋工学、社会システム・防災工学、エネルギー・資源工学 等
B19: 材料・プロセス・応用医工学 | C19: 材料、界面、プロセス、ナノスケール構造、応用物性、生体適合技術を対象に、機能創出と応用実装を進める研究領域。 | E19: 材料工学、化学工学、ナノ・マイクロ科学、応用物性、人間医工学 等
B20: 電気工学・電子工学・情報科学・コンピューターサイエンス | C20: 電気・電子・光・制御・計測・通信・デバイスや、計算、ソフトウェア、データ、ネットワーク、知能情報処理を扱う研究領域。 | E20: 電気電子工学、応用物理・デバイス工学、情報科学・情報工学、人間情報・応用情報 等
B21: 数学・物理学・地球科学 | C21: 数理構造、自然法則、地球・宇宙システムの基礎原理を理論・観測・実験・解析で解明する研究領域。 | E21: 代数・幾何学、解析・応用数学、物性物理学、宇宙物理学、天文学、地球惑星科学 等
B22: 農学・環境学・生態学 | C22: 生物資源、農業生産、食料、環境保全、生態系維持を扱う研究領域。 | E22: 農芸化学、生産環境農学、森林・水圏科学、農業工学・農業経済、環境評価・環境保全 等
B23: 社会科学 | C23: 人間の行動、制度、組織、市場、政策、社会構造を理論的・実証的に分析する研究領域。 | E23: 文化人類学、法制度、政治学、経済・経営学、社会学、教育学、心理学 等
B24: 芸術・人文科学 | C24: 文化、歴史、思想、言語、表現、価値形成を解釈・批評・史資料分析により探究する研究領域。 | E24: 哲学、芸術学、文学・言語、歴史学、考古学 等
A26: 【参考：ユースケース分類】
B28: 開発／利用 | C28: ユースケースの分類 | D28: 定義・判断基準 | E28: 具体イメージ
B29: 開発 | C29: 学習用データセット構築 | D29: 今後のAI・深層学習での活用を前提としたデータ収集や加工の過程が主である場合は本ユースケースに該当（実験やフィールドワーク等によるデータ収集も含む） | E29: ・古文書のデジタイズ・前処理・メタデータ整備により「AI ready」に ・化学における機械学習ポテンシャル開発のため学習データセット整備
C30: 既存モデルの適応 | D30: 既存の基盤モデルを、事後学習・ファインチューニングにより、軽量化・高速化・最適化することが主な場合は本ユースケースに該当（学習を伴わないRAGの構築などは、本ユースケースでなく、「利用」が該当） | E30: ・基盤モデルをファインチューニングし、多様な科学文書から半導体材料に関わる情報を抽出・構造化して整理するモデルを開発 ・基盤LLMをベースに、低コストで運用しやすい小規模なモデルを開発​
C31: AIモデル開発 | D31: 自らモデル構築し、データ収集・事前学習・微調整・検証・評価の一連のサイクルが全て含まれる場合は本ユースケースに該当（大規模言語モデルに限らず、深層学習を活用した研究を含む） | E31: ・生物実験のスケジュールや自動化できる小規模AIモデルの開発 ・流体方程式を組み込んだ物理系のAIシミュレーションの開発​ ・素粒子加速実験におけるジェット分類を行う深層学習モデル開発​
C32: 既存モデル評価 | D32: 既存モデルの「検証・評価・改善」を主目的としている研究は本ユースケースに該当。AIの改善を目的としていれば、仕組みの理解（例：プロービング）の研究も本ユースケースに該当 | E32: ・注意機構を分析することにより、ハルシネーションの少ないAIを開発するための示唆を抽出 ・"LLM-as-a-judge" の信頼性向上にむけた研究
B33: 利用 | C33: 実験自動化・自律化 | D33: 物理的な実験装置・ロボット・機械等の接続が含まれる場合は本ユースケースに該当 (ただし、本事業期間中はコード開発等に留まり、実際の器具等を扱わない場合、本ユースケースでなく、他の分類から最適なものを選択)​ | E33: ・カメラと連携し、作物の病気の予兆を検出するAIカメラの開発 ・ロボアームと連携し、小規模な実験を自立的に遂行するAI開発
C34: シミュレーション・デジタルツイン | D34: 既存のAIを利用(※)が主で、現時点では「実際の実験・観測」による研究が必要なプロセスを、シミュレーション・デジタルツインにより代替することを企図する研究が該当（スクラッチでのモデル開発の場合は「AIモデル開発」に該当） | E34: ・言語獲得の過程を、LLMを人間に見立てシミュレーションする研究 ・AIエージェントを用いることで「社会」をシミュレーション研究​ ・バーチャル臓器による臨床試験のプロトタイプを開発​
C35: 発見・設計支援 | D35: 既存のAIを利用(※)が主で、仮説生成から実験計画など、「実際の実験・解析」などに至る前段階のプロセスをAIにより効率化・自立化する場合が該当 | E35: ・既存AIを活用し、産業動向等を踏まえつつ研究ネクストステップの仮説や産学連携の案を提示するシステムを開発 ・材料設計において、実験前の段階で筋の良い材料探索をAIで実施​
C36: 高度データ解析・モデリング | D36: 既存のAIを利用(※)が主で、（シミュレーション・デジタルツインに該当するもの以外で）データ分析・予測の高度化をはかる研究が広く該当（ただし、自ら一連のモデル構築を行う研究は「AIモデル開発」に該当） | E36: ・SNSのデータをリアルタイムにAIにより分析し、社会情勢を可視化 ・地震発生の長期予測モデルに必要なパラメータを、AIを活用し推定
B37: その他 | C37: その他 | D37: 主として理論的な研究や、「Science for AI」に近い研究、また、AIに関するメタサイエンス等、上記に当てはまらないユースケースや研究等 (※可能な限り、上記の分類からご選択ください) | E37: ・AIを科学研究に導入することそのものへの、社会的インパクトの分析 ・非平衡統計力学の知見を用いてAIの新たなアーキテクチャを理論的に検討
B38: (※) 既存のAIを利用 : ChatGPT等の既存モデルをサービスあるいはAPI経由で利用したり、SaaS・AutoML系のサービス等を利用することを指す​
A40: 【府省共通経費取扱区分表について】
B42: １．総論 (1)府省共通経費取扱区分表（以下、「区分表」という。）は、各競争的研究費制度において共通して使用するものであり、以下にその解釈及び運用について確認する。 (2)各制度は、区分表及び本取扱に基づきあらかじめ費目構成を設定し、経費の取扱を明確に示す。 ２．費目の設定について (1)各制度は、区分表に記載された費目の名称を用いるものとする。 (2)経費の種類は、「直接経費」「間接経費」「再委託費・共同実施費」の３種類とする。 (3)「直接経費」には、「大項目」を設け、大項目にはさらに「中項目」を設ける。 (4)「直接経費」の大項目は、「物品費」「人件費・謝金」「旅費」「その他」の４項目に統一する。 (5)中項目は、以下に統一する。 ・大項目「物品費」の中項目に「設備備品費」「消耗品費」を設定する。 ・大項目「人件費・謝金」の中項目に「人件費」「謝金」を設定する。 ・大項目「旅費」には中項目に「旅費」を設定する。 ・大項目「その他」の中項目に「外注費」「印刷製本費」「会議費」「通信運搬費」「光熱水料」「その他（諸経費）」「消費税相当額」を設定する。 (6)実績報告等は大項目単位によることを原則とし、必要に応じて中項目のうち額の報告を求めるものについては、配分機関は当該区分表の「中項目の設定・取扱等」欄に明記する。また、中項目自体を設定しない場合は、同様に「中項目の設定・取扱等」欄に明記することとする。 ３．費目の解釈について (1)直接経費の各費目、間接経費及び再委託費・共同実施費の解釈を統一するために、区分表に解説（太字下線部分）を記載した。 (2)直接経費の各費目については、研究者等が混乱なく研究費を使用できるように、各制度において共通的なものとして、具体的な支出の例示を区分表に記載した。 ４．各制度における区分表の運用について (1)各制度における事業の性質等により、「中項目の具体的な支出の例示」欄で示した経費のうち、当該中項目の経費とすることが適当でない場合、また、支出にあたり一定の条件を付す場合などには、区分表の「特記事項」欄で明示することとする。 (2)中項目の「設備備品費」「消耗品費」「消費税相当額」は、制度の種類により適用を異にするものであるので、各制度においては、これらの取扱について、区分表の「特記事項」欄で記述することとする。なお委託費における「設備備品費」「消耗品費」の定義は、「中項目の具体的な支出の例示」欄に明瞭に記載することとする。 (3)上記(1)及び(2)により制度としての調整を施された区分表は、例えば各制度のホームページに掲載することなどにより、公開を進めることとする。 (4)区分表は各制度共通に使用するものではあるが、主に企業への資金配分を行っている制度であって、会計処理や経費区分が本区分表と異なる運用をしている研究機関の負担に配慮し、それぞれの研究機関により適切な経費管理が可能となるよう、配分機関は本区分表を参考に費目を設定できることとする。
A44: 【費用詳細（API費用・計算資源費用）の記載について】
B46: 本欄には、AIの利用に伴う費用の内訳について、項目ごとに整理して記載してください。複数の用途がある場合や、複数種類のGPU等を利用する場合は、用途やGPU等の種類ごとに分けて記載してください。 ＜各項目の記載内容 API費用＞ 従量課金制のAPI費用については、下記の例を参照して記載してください。なお、従量課金制かどうかにかかわらず、データ取得・照会・連携のためにAPIを利用した場合等についても、適宜記載してください。 ■処理対象 処理対象となるデータを記載してください。（例）文献、実験ログ、画像、動画、音声データ ■金額 当該用途に係る費用の合計額を記載してください（千円単位）。 ■算定根拠 API費用の見積もり根拠を具体的に記載してください。（含めてほしい観点の例）データ処理に係る量や頻度、再実行率等 ＜各項目の記載内容 計算資源費用 (クラウドGPU含む)＞ ■GPU種類 利用を想定している計算資源（GPU等）の種類を記載してください。（例）NVIDIA社のA100、V100 等 ■当該GPUを選定した理由 利用目的や性能要件等、当該GPUを選定した理由について、簡潔に記載してください。（含めてほしい観点の例）当該研究に求められる処理速度や処理対象となるデータ等 ■金額 当該用途に係る費用の合計額を記載してください（千円単位）。 ■算定根拠 計算資源（クラウド）の利用料金の見積もり根拠を具体的に記載してください。（含めてほしい観点の例）データ処理に係る量や頻度

Sheet 参考）府省共通経費取扱区分表
A2: 府省共通経費取扱区分表
E3: 制度・事業名： AI for Science萌芽的挑戦研究創出事業（SPReAD）
B5: 大項目 | C5: 中項目 | D5: 中項目の具体的な支出の例示 | E5: 中項目の設定・ 取扱等 | F5: 特記事項
A6: 直接経費 | B6: 物品費 | C6: 設備備品費 | D6: 業務・事業の実施に必要な機械装置、工具器具備品等の購入、製造又はその据付等に要する経費。装置等の改造（主として機能を高め、又は耐久性を増すための資本的支出）及びソフトウエア（機器・設備類に組み込まれ、又は付属し、一体として機能するもの）を含む。 | E6: 計算資源を物品として取得する場合（例：GPU搭載機器の購入等）については、「設備備品費」として計上するとともに、研究計画調書_4枚目の「計算資源費用(クラウドGPU含む）」としても計上してください。 | F6: GPU搭載サーバ、ワークステーション、研究用ストレージ装置その他これらに類する計算機器を物品として取得する場合であって、備品として管理すべきものは、「設備備品費」に計上してください。
C7: 消耗品費 | D7: 業務・事業の実施に直接要した以下に例示する資材、部品、消耗品等の購入経費。 ・ソフトウェア ※バージョンアップを含む ・図書、書籍 ※年間購読料を含む ・パソコン周辺機器、CD-ROM、DVD-ROM等 ・実験動物、試薬、試薬キット、実験器具類 ・試作品 等 | F7: 安価な周辺機器、記録媒体、交換部材その他計算機器を物品として取得する場合で、消耗品として管理すべきものは「消耗品費」として計上してください。
B8: 人件費 ・謝金 | C8: 人件費 | D8: 業務・事業に直接従事した者の人件費で主体的に研究を担当する研究者の経費 ・研究採択者本人の人件費（有給休暇等を含む）及び法定福利費、通勤費、住宅手当、扶養手当、勤務地手当、委託試験に係る退職手当等 ・ポスドク等、機関で直接雇用する研究員の人件費（有給休暇等を含む）及び法定福利費、通勤費、住宅手当、扶養手当、勤務地手当、委託試験に係る退職手当等 ・特殊機器操作、派遣業者からの派遣研究員の費用 ・他機関からの出向研究員の経費 等 業務・事業に直接従事した者の人件費で補助作業的に研究等を担当する者の経費 ・リサーチアドミニストレーター、リサーチアシスタント ・研究補助作業を行うアルバイト、パート、派遣社員 ・技術補佐員、教務補佐員、事務補佐員、秘書 等 ＊人件費の算定にあたっては、研究機関の給与規程等によるものとする。 | F8: 本事業において人件費の支出は対象外となります。
C9: 謝金 | D9: 業務・事業の実施に必要な知識、情報、技術の提供に対する経費 ・研究運営委員会等の外部委員に対する委員会出席謝金 ・講演会等の謝金 ・個人の専門的技術による役務の提供への謝金（講義・技術指導・原稿の執筆・査読・校正（外国語等）等） ・データ・資料整理等の役務の提供への謝金 ・通訳、翻訳の謝金（個人に対する委嘱） ・学生等への労務による作業代 ・被験者の謝金 等 ＊謝金の算定にあたっては、研究機関の謝金支給規程等によるものとする。
B10: 旅費 | C10: 旅費 | D10: 旅費に関わる以下の経費 ①業務・事業を実施するにあたり研究者及び補助員（学部学生・大学院生を含む）の外国・国内への出張又は移動にかかる経費（交通費、宿泊費、日当、旅行雑費）。学会へ参加するための交通費、宿泊費、日当、旅行雑費を含む。 ②上記①以外の業務・事業への協力者に支払う、業務・事業の実施に必要な知識、情報、意見等の収集のための外国・国内への出張又は移動にかかる経費（交通費、宿泊費、日当、旅行雑費） ③外国からの研究者等（大学院生を含む）の招へい経費（交通費、宿泊費、日当、滞在費、旅行雑費） ④研究者等が赴帰任する際にかかる経費（交通費、宿泊費、日当、移転費、扶養親族移転費、旅行雑費） 等 ＊旅費の算定にあたっては、研究機関の旅費規程等によるものとする。 ＊旅費のキャンセル料（やむを得ない事情からキャンセル料が認められる場合のみ）を含む。 ＊「旅行雑費」とは、「空港使用料」「旅券の交付手数料」「査証手数料」「予防注射料」「出入国税の実費額」「燃油サーチャージ」「航空保険料」「航空券取扱手数料」等をいう。
B11: その他 | C11: 外注費 | D11: 外注に関わる以下の経費 業務・事業に直接必要な装置のメンテナンス、データの分析等の外注にかかる経費 ・機械装置、備品の操作・保守・修理（原則として当事業で購入した備品の法定点検、定期点検及び日常のメンテナンスによる機能の維持管理、原状の回復等を行うことを含む）等の業務請負 ・実験動物等の飼育、設計（仕様を指示して設計されるもの）、試験、解析・検査、鑑定、部材の加工等の業務請負 ・通訳、翻訳、校正（校閲）、アンケート、調査等の業務請負（業者請負） 等 ＊「再委託費・共同実施費」に該当するものを除く
C12: 印刷製本費 | D12: 業務・事業にかかる資料等の印刷、製本に要した経費 ・チラシ、ポスター、写真、図面コピー等研究活動に必要な書類作成のための印刷代 等
C13: 会議費 | D13: 業務・事業の実施に直接必要な会議・シンポジウム・セミナー等の開催に要した経費 ・研究運営委員会等の委員会開催費 ・会場借料 ・国際会議の通訳料 ・会議等に伴う飲食代・レセプション代（アルコール類は除く） 等
C14: 通信運搬費 | D14: 業務・事業の実施に直接必要な物品の運搬、データの送受信等の通信・電話料 ・電話料、ファクシミリ料 ・インターネット使用料 ・宅配便代 ・郵便料 等
C15: 光熱水料 | D15: 業務・事業の実施に使用する機械装置等の運転等に要した電気、ガス及び水道等の経費
C16: その他 （諸経費） | D16: 上記の各項目以外に、業務・事業の実施に直接必要な経費 ・物品等の借損（賃借、リース、レンタル）及び使用にかかる経費、倉庫料、土地・建物借上料、圃場借料 ・研究機関内の施設・設備使用料 ・学会参加費（学会参加費と不可分なランチ代・バンケット代を含む。学会に参加するための旅費は『旅費』に計上） ・学会参加費等のキャンセル料（やむを得ない事情からキャンセル料が認められる場合のみ） ・研究成果発表費（論文審査料・論文投稿料（論文掲載料）・論文別刷り代、成果報告書作成・製本費、テキスト作成・出版費、ホームページ作成費等） ・広報費（ホームページ・ニュースレター等）、広告宣伝費、求人費 ・保険料（業務・事業に必要なもの） ・振込手数料 ・データ・権利等使用料（特許使用料、ライセンス料（ソフトウェアのライセンス使用料を含む）、データベース使用料、クラウド利用料等） ・特許関連経費 ・薬事相談費 ・薬品・廃材等処理代 ・書籍等のマイクロフィルム化・データ化 ・レンタカー代、タクシー代（旅費規程により『旅費』に計上するものを除く） ・研究以外の業務の代行に係る経費（バイアウト経費） 等 | E16: APIを利用するために要する経費（例：従量課金制によるAPI利用料、AIモデルその他の解析用APIの利用料、データ取得・照会・連携のために利用するAPIの利用料、データベース又は外部プラットフォームにAPIを通じてアクセスするための利用料等）は、研究計画調書_4枚目の「API費用」として計上してください。 また、計算資源の調達・利用において、利用・賃借・使用に係る経費（例：民間クラウドサービスの利用料、GPU搭載機器のリース料・レンタル料、研究機関内のHPCやGPUクラスター等の利用料、ソフトウェアライセンス料・サブスクリプション料等）は、研究計画調書_4枚目の「計算資源費用(クラウドGPU含む）」として計上してください。 | F16: その他（諸経費）として、AI for Scienceの波及・振興に資する次世代を担う理工系分野の人材育成の促進に係る経費の支出を可能としております。 ・理数系の博士号取得者等によるオンラインでの小・中・高等学校における理科、物理、化学等の授業や出前講座に係る費用 ・研究成果を中高生等が理解しやすいコンテンツとして SNS 等で配信するための費用 なお、本事業において「研究以外の業務の代行に係る経費（バイアウト経費）」の支出については対象外となります。
C17: 消費税相当額 （委託費のみ） | D17: 「人件費のうち通勤手当を除いた額」、「外国旅費・外国人等招へい旅費のうち支度料や国内分の旅費を除いた額」、「諸謝金」及び「保険料」の１０％に相当する額等、消費税に関して非（不）課税取引となる経費 | F17: 本事業は補助事業ですので、本事項は対象外です。
A19: 間接経費 | D19: 直接経費に対して一定比率で手当され、競争的研究費による研究の実施に伴う研究機関の管理等に必要な経費として、被配分機関が使用する経費。
A21: 再委託費・共同実施費 | D21: 委託先が委託業務の一部をさらに第三者に委託又は第三者と共同で実施するための経費（間接経費相当分を含む） | F21: 本事業は補助事業ですので、本事項は対象外です。

Sheet 研究計画調書_1枚目
A1: 様式1 | M1: 日本語 | N1: 1枚目
B2: 令和8年度 AI for Science萌芽的挑戦研究創出事業（SPReAD）研究計画調書
G6: 提出日 | I6: 年 | K6: 月 | M6: 日
B7: 応募者情報
B8: e-Rad 研究者番号 (8桁の半角数字)
C9: ※研究代表者本人が研究者番号を持たない場合は、代理で申請を行う指導教員等の番号をご記載ください。 ※Excelの仕様上、冒頭の「0」が表示されないことがございますが、審査上は問題ございません。
B10: メールアドレス
C11: ※必ず、所属機関から発行されている研究代表者本人のメールアドレスをご使用ください。
B12: 研究代表者氏名 | C12: フリガナ
C13: 漢字
C14: ※姓と名は半角で1スペース空けてください。
B15: 生年月日 (西暦、半角数字) | E15: 年 | G15: 月 | I15: 日
B16: e-Rad所属機関コード(半角数字)
C17: ※科研費の機関番号とは異なりますのでご留意ください。ご不明な場合は、e-Rad上ないしは所属機関にご確認ください。
B18: 所属機関
B19: 部局
B20: 職 | H20: 学生の場合のみプルダウンから「Y」をご選択ください。→
B21: 所属機関の区分
C22: ※最も近しいものをプルダウンからご選択ください。 ※プルダウンが使えない場合、「リスト」タブの「所属機関の区分」の中から該当のものを選択し、転記ください。
B23: 応募者属性の区分
C24: ※最も近しいものをプルダウンからご選択ください。 ※プルダウンが使えない場合、「リスト」タブの「応募者属性の区分」の中から該当のものを選択し、転記ください。
B26: 研究課題情報
B27: 研究領域
C28: ※「はじめにご確認ください）記入にあたっての留意事項」タブを参照し、最も近しいものをプルダウンからご選択ください。 ※プルダウンが使えない場合、「はじめにご確認ください）記入にあたっての留意事項」タブの「参考：研究領域分類」のB列「研究領域」から該当のものを選択し、転記ください。
B29: メインユースケース分類
C30: ※「はじめにご確認ください）記入にあたっての留意事項」タブを参照し、最も近しいものをプルダウンからご選択ください。 ※プルダウンが使えない場合、「はじめにご確認ください）記入にあたっての留意事項」タブの「参考：ユースケース分類」のC列「ユースケースの分類」から該当のものを選択し、転記ください。
B31: 「9.その他」を選択した場合(自由記述)
B32: サブユースケース選択 | D32: 1.学習用データセット構築 | F32: 2.既存モデルの適応 | H32: 3.AIモデル開発 | J32: 4.既存モデル評価
D33: 5.実験自動化・ 自律化 | F33: 6.シミュレーション・ デジタルツイン | H33: 7.発見・設計支援 | J33: 8.高度データ解析・ モデリング
C34: ※「はじめにご確認ください）記入にあたっての留意事項」タブを参照し、メインユースケースを達成するための補助目的として該当するものすべてに、プルダウンで「Y」をつけてください。 | N34: 文字数カウント
B35: 研究課題名 | N35: =LEN(C35) -> 0
C36: (日本語：50文字程度) ※上記文字数は目安となります。
B38: AI活用度
B39: AI活用度選択(複数選択可) | D39: 研究でAIをまったく使っていない | F39: 研究そのもの以外の業務（メール・翻訳等）でAIを使っている | H39: 研究における文献探索や要約にAIを使っている | J39: 論文執筆や研究発表資料作成にAIを使っている | L39: 仮説検討やアイデア出しにAIを使っている
D40: 研究データをAI (含: 自ら作成した深層学習コード 等) で分析・処理をしたことがある | F40: AIや深層学習による分析結果を、論文・発表などにおいて研究成果として発表したことがある | H40: APIにより既存AIを研究プロセスに組み込んでいる | J40: 自分でAI・深層学習モデルの開発 (学習・評価の一連のプロセス全てを含む)を行い、研究に活用したことがある | L40: 新しい基盤モデル開発の経験がある
C41: ※直接的に採択可否には影響しません。 ※該当するものすべてに、プルダウンで「Y」をつけてください。
B42: 現在の具体的な活用方法 | N42: =LEN(C42) -> 0
C43: (日本語：200字程度) ※上記文字数は目安となります。
B45: 研究経費
B46: 研究経費(半角数字) | C46: 研究経費(千円) | E46: 内訳（千円）
...

Sheet 研究計画調書_2枚目
A1: 様式1 | E1: 日本語 | F1: 2枚目
B2: 令和8年度 AI for Science萌芽的挑戦研究創出事業（SPReAD）研究計画調書
B3: 注意事項 ■ 必ず公募要領の「4.応募する方へ（３）応募書類（研究計画調書）の作成・応募方法等」を参照のうえ、記載をお願いいたします。 ■ 説明は、原則として文章により記述してください。なお、色を付した図や文字が使用された研究計画調書はそのまま審査に付されます。 ■ 図表を用いた説明が必要な場合には、後段に設ける図表掲載欄において提示してください。
B6: # | C6: 項目 | D6: 記入欄 | E6: 文字数カウント ※既定文字数に満たない/超える場合に赤くエラーが表示されます。
B8: 1 | C8: 研究目的 研究課題の内容及びその目的について、何のためにどのような研究を行うのかを具体的に記載してください。対象とする現象・課題、解決しようとする問題、得ようとする知見等を明確に示してください。 ＜文字数制限＞ 日本語：80文字以上400文字以内 | E8: =LEN($D8) -> 0
B9: 2 | C9: 研究方法 研究目的を達成するための具体的な方法を記載してください。研究プロセスを工程ごとに整理し、それぞれの工程においてAIをどのように適用又は開発するかを明確に示してください。また、使用するデータの種類・取得方法、評価指標及び検証方法についても可能な限り具体的に記載してください。 ＜文字数制限＞ 日本語：160文字以上800文字以内 | E9: =LEN($D9) -> 0
B10: 3 | C10: AI利活用の妥当性・実現可能性 当該研究課題においてAIを利活用する必要性及び妥当性について記載してください。従来手法では対応が困難である点や、AIを利活用することで実現可能となる事項を具体的に示し、当該研究におけるAI利活用の意義が明確となるようにしてください。 ＜文字数制限＞ 日本語：160文字以上800文字以内 | E10: =LEN($D10) -> 0
B11: 4 | C11: 達成目標 本研究課題が最終的に目指す到達目標を簡潔に示した上で、本事業の研究実施期間（約180日）において達成を目指す事項を具体的に記載してください。なお、最終的な到達目標は、補助事業期間終了後に達成される目標や将来的な研究展開を含むものでも差し支えありません。 その上で、本事業の研究実施期間内において、当該最終目標に向けてどの段階まで研究を前進させるのかについて、中間（３か月後）及び補助事業期間終了時（６か月後）における到達目標や成果物を区分し、試作、PoC、予備的検証等を含めて具体的に記載してください。 ＜文字数制限＞ 日本語：100文字以上500文字以内 | E11: =LEN($D11) -> 0
B12: 5 | C12: AI利活用のノウハウ抽出・共有の実現計画 本事業では、AI for Scienceの知見を共有するコミュニティ形成を行います。本研究を通じて得られるAI利活用の知見について、どのように整理・抽出し、当該コミュニティにおいて、共有・展開するかを記載してください。各工程における利活用方法や課題を体系的に整理し、他の研究分野においても利活用可能な形での共有を意識して記載してください。 ＜文字数制限＞ 日本語：60文字以上300文以内 | E12: =LEN($D12) -> 0
B13: 6 | C13: 成果の公開方針（任意） 研究により得られる成果について、公開を予定している内容及び公開方法を記載してください。 （例：論文、研究データ、ソースコード、プロトタイプ、報告書等） ＜文字数制限＞ 日本語：150文字以内 | E13: =LEN($D13) -> 0
B14: 7 | C14: 研究業績等 当該研究課題に関連して、主要な業績（学術論文・学会発表・著書のいずれか）を有する場合には、各セルに1件ずつ合計で最大5件まで、箇条書きで記載してください。 なお、当該業績については、研究代表者本人を含む業績のみを記載ください。 ・学術論文：「題名」「著者名（本人に下線）」「掲載誌名」「発行年月」を記すこと。「被引用数」を付記してもよいが、その場合、情報源・取得日を明記すること。 ・学会発表：「題名」「著者名（本人に下線）」「学会名」「発表年月」を記すこと。当該学会において受賞等があった場合、その旨を追記してもよい。 ・著書：「書名」「著者名（本人に下線）」「発行所」「発行年月」を記すこと。「分担項目名」を記してもよい。
B20: 【参考：図の貼付】 研究内容の理解を促進するため、研究プロセスやAIの適用箇所等を示す図をこの欄より下に適宜貼付してください。 図は簡潔かつ分かりやすい構成とし、文章では伝わりにくい関係性や流れを補足するものとしてください（最大1枚）。 ※セルに画像を挿入する必要はございません

Sheet 研究計画調書_3枚目
A1: 様式1 | N1: 日本語 | O1: 3枚目
B2: 令和8年度 AI for Science萌芽的挑戦研究創出事業（SPReAD）研究計画調書
B3: 研究経費とその必要性
B4: 注意事項 ■ 研究計画において、「設備備品費」、「旅費」又は「謝金」のいずれかの経費が９０％を超える研究計画の場合及びその他（消耗品費、その他）の費目で特に大きな割合を占める経費がある研究計画の場合には、当該経費の研究遂行上の必要性について、研究計画調書に記載しなければなりません。 ■ 総計欄は自動で計算されるようになっています。金額を記載の際には、必ず半角数字とし、千円未満の端数は切り捨ててください。 ■ 間接経費は含まず、直接経費のみ記載ください。 ■ 記入の際には、「はじめにご確認ください）記入にあたっての留意事項」および「参考）府省共通経費取扱区分表」を必ずご参照ください。 ■ 「その他」に API 又は計算資源（クラウド GPU を含む）に係る経費を計上する場合は、その内容の詳細を「研究計画調書_4枚目」に記入してください。 ■ また、計算資源を物品として取得し「設備備品費」として計上する場合についても、その内容の詳細を「研究計画調書_4枚目」に記入してください。
B7: 1 | C7: 設備備品費、消耗品費
C9: 設備備品費の明細 | L9: 消耗品費の明細
C10: # | D10: 事項 | E10: 設置機関 | G10: 単価(千円) | I10: 数量 | J10: 金額(千円) | L10: # | M10: 事項 | N10: 金額(千円)
C11: 1 | J11: =G11*I11 -> 0 | L11: 1
C12: 2 | J12: =G12*I12 -> 0 | L12: 2
C13: 3 | J13: =G13*I13 -> 0 | L13: 3
C14: 4 | J14: =G14*I14 -> 0 | L14: 4
C15: 5 | J15: =G15*I15 -> 0 | L15: 5
C16: 6 | J16: =G16*I16 -> 0 | L16: 6
C17: 7 | J17: =G17*I17 -> 0 | L17: 7
C18: 8 | J18: =G18*I18 -> 0 | L18: 8
C19: 9 | J19: =G19*I19 -> 0 | L19: 9
C20: 10 | J20: =G20*I20 -> 0 | L20: 10
C21: 11 | J21: =G21*I21 -> 0 | L21: 11
C22: 12 | J22: =G22*I22 -> 0 | L22: 12
... C30: 20 | J30: =G30*I30 -> 0 | L30: 20
C31: 総計 | J31: =SUM(J11:J30) -> 0 | L31: 総計 | N31: =SUM(N11:N30) -> 0
C33: 設備備品費、消耗品費の必要性
B36: 2 | C36: 謝金、旅費
C38: 謝金の明細 | G38: 国内旅費の明細 | L38: 外国旅費の明細
C39: # | D39: 事項 | E39: 金額(千円) | G39: # | H39: 事項 | J39: 金額(千円) | L39: # | M39: 事項 | N39: 金額(千円)
C40: 1 | G40: 1 | L40: 1
C41: 2 | G41: 2 | L41: 2
C42: 3 | G42: 3 | L42: 3
C43: 4 | G43: 4 | L43: 4
C44: 5 | G44: 5 | L44: 5
C45: 6 | G45: 6 | L45: 6
C46: 7 | G46: 7 | L46: 7
C47: 8 | G47: 8 | L47: 8
C48: 9 | G48: 9 | L48: 9
C49: 10 | G49: 10 | L49: 10
C50: 11 | G50: 11 | L50: 11
C51: 12 | G51: 12 | L51: 12
... C59: 20 | G59: 20 | L59: 20
C60: 総計 | E60: =SUM(E40:E59) -> 0 | G60: 総計 | J60: =SUM(J40:J59) -> 0 | L60: 総計 | N60: =SUM(N40:N59) -> 0
C62: 謝金、旅費の必要性
...

Sheet 研究計画調書_4枚目
A1: 様式1 | G1: 日本語 | H1: 4枚目
B2: 令和8年度 AI for Science萌芽的挑戦研究創出事業（SPReAD）研究計画調書
B3: 研究経費とその必要性
B4: 注意事項 ■ 本欄には、AIの利用に伴う費用の内訳について、項目ごとに整理して記載してください。 複数の用途がある場合や、複数種類のGPU等を利用する場合は、用途やGPU等の種類ごとに分けて記載してください。
C7: 費用詳細 API費用
C8: # | D8: 処理対象 | E8: 金額(千円) | F8: 算定根拠（1回あたりの入力量/出力量、反応速度、再実行率等）
C9: 1
C10: 2
C11: 3
C12: 4
C13: 5
C14: 6
C15: 7
C16: 8
C17: 9
C18: 10
C20: 費用詳細 計算資源費用 (クラウドGPU含む)
C21: # | D21: GPU種類 | E21: 当該GPUを選定した理由 | F21: 金額(千円) | G21: 算定根拠（データ処理に係る量や頻度 等）
C22: 1
C23: 2
C24: 3
C25: 4
C26: 5
C27: 6
C28: 7
C29: 8
C30: 9
C31: 10

Sheet リスト
A1: 研究領域 | B1: ユースケース分類 | C1: 所属機関の区分 | D1: 応募者の属性区分
A2: 臨床科学 | B2: 1.学習用データセット構築 | C2: 大学 | D2: 教員
A3: 生命科学・薬学 | B3: 2.既存モデルの適応 | C3: 高等専門学校 | D3: 研究員(ポスドク含む)
A4: 化学 | B4: 3.AIモデル開発 | C4: 公的研究機関 | D4: 博士課程学生
A5: 機械・社会基盤・エネルギー工学 | B5: 4.既存モデル評価 | C5: 民間企業 | D5: 修士課程学生
A6: 材料・プロセス・応用医工学 | B6: 5.実験自動化・自律化 | C6: 非営利団体・公益法人 | D6: 学部学生
A7: 電気工学・電子工学・情報科学・コンピューターサイエンス | B7: 6.シミュレーション・デジタルツイン | C7: その他（上記のいずれにも該当しない場合に限る） | D7: 技術職員・事務職員・URA等
A8: 数学・物理学・地球科学 | B8: 7.発見・設計支援 | D8: 技術者・開発者
A9: 農学・環境学・生態学 | B9: 8.高度データ解析・モデリング | D9: その他（上記のいずれにも該当しない場合に限る）
A10: 社会科学 | B10: 9.その他
A11: 芸術・人文科学
