Workbook

Sheet Notes) Important Notes for Fill
A1: Important Notes for Completing the Research Plan
B3: No | C3: Item | D3: Notes
B4: 1 | C4: Checking Input Content | D4: Cells that have not been filled in are displayed in light orange. Before submission, please make sure all required fields (light orange cells) have been completed. *Light orange cells indicate unfilled fields, but not all fields are mandatory. Fields that do not apply to you or that do not require input do not need to be filled in.
B5: 2 | C5: Checking Character Count Limits | D5: For fields with character count limits, always check the character count display and ensure your text is within the specified range. Please note that exceeding or falling short of the character limit may result in the document being deemed incomplete and "rejected." ★ If the upper or lower limit is not met, the character count will be displayed in red.
B6: 3 | C6: Structure of the Research Plan | D6: The structure of the Research Plan is as follows. There are a total of 4 tabs that applicants must fill in. ・Notes) Important Notes for Filling Out This Form ・Reference) Government-Wide Expense Classification Table ・Research Plan_Sheet 1: Basic Information ・Research Plan_Sheet 2: Research Objectives, Methods, etc. ・Research Plan_Sheet 3: Research Expense Breakdown ・Research Plan_Sheet 4: Details of Cost Basis for API / Computational Resources *Fill in only if applicable
B7: 4 | C7: Handling of the Template (Format) | D7: Editing of this document beyond the designated input fields is generally restricted. Please do not change the layout or formatting unless absolutely necessary.
B8: 5 | C8: File Name for the Research Plan | D8: In the file name "Form1_2nd_ResearchPlan_e-RadInstitutionCode_RomanizedName," please update "e-RadInstitutionCode" and "RomanizedName" with your own information. Enter the e-Rad institution code using half-width numerals, and your name in romanized half-width letters in the order of family name followed by given name, with a half-width space between them.
B9: 6 | C9: Research Expenses | D9: In the "Research Expenses" section on Sheet 1, if the total research budget is less than 100,000 yen or exceeds 5,000,000 yen, an error will be displayed in red. When entering amounts, always use half-width numerals and round down any amount less than 1,000 yen.
B10: 7 | C10: Other | D10: For the definitions of research areas and use cases, please refer to the information provided below and select the most appropriate option for your research. For research expenses, please refer to the "About the Government-Wide Expense Classification Table" section below and the separate tab "Reference) Government-Wide Expense Classification Table."
A12: [Reference: Research Area Classification]
B14: Research Area | C14: Definition | E14: Research Fields (Examples)
B15: Clinical Science | C15: A research area that generates and verifies knowledge targeting patients, populations, and healthcare settings with the aim of diagnosing, treating, preventing, and improving the prognosis of diseases. | E15: Internal medicine, organ-specific internal medicine / bioinformation medicine, surgery, functional and sensory surgery, oral science, social medicine / nursing, sports science, veterinary medicine, etc.
B16: Life Sciences / Pharmacy | C16: A research area that elucidates life phenomena at the molecular, cellular, and individual levels and extends to drug discovery, pharmacology, and biological regulation. | E16: Cell biology, evolutionary biology, neuroscience, pharmacy, biostructure and function, pathology, oncology, brain science, etc.
B17: Chemistry | C17: A research area that deals with the structure, reactions, properties, synthesis, and transformation of atoms, molecules, and materials to create new substances and functions. | E17: Physical chemistry, organic chemistry, inorganic / complex / analytical chemistry, polymer and organic materials, inorganic materials and energy chemistry, biomolecular chemistry, etc.
B18: Mechanical / Infrastructure / Energy Engineering | C18: A research area that performs design, control, and implementation for machinery, structures, fluid / thermal systems, mobile bodies, architecture / civil engineering, social infrastructure, safety / disaster prevention, and energy systems. | E18: Materials mechanics / design / production engineering, fluid and thermal engineering, mechanical dynamics / robotics, civil engineering, architecture, aerospace / marine engineering, social systems / disaster prevention engineering, energy and resource engineering, etc.
B19: Materials / Process / Applied Biomedical Engineering | C19: A research area that advances functional creation and applied implementation targeting materials, interfaces, processes, nanoscale structures, applied physical properties, and biocompatibility technologies. | E19: Materials engineering, chemical engineering, nano / micro science, applied physical properties, human biomedical engineering, etc.
B20: Electrical Engineering / Electronic Engineering / Information Science / Computer Science | C20: A research area that covers electrical, electronic, optical, control, measurement, communications, and device systems, as well as computation, software, data, networks, and intelligent information processing. | E20: Electrical and electronic engineering, applied physics and device engineering, information science and engineering, human information and applied information, etc.
B21: Mathematics / Physics / Earth Sciences | C21: A research area that elucidates mathematical structures, laws of nature, and the fundamental principles of Earth and space systems through theory, observation, experiment, and analysis. | E21: Algebra / geometry, analysis / applied mathematics, condensed matter physics, astrophysics, astronomy, earth and planetary science, etc.
B22: Agriculture / Environmental Science / Ecology | C22: A research area that deals with biological resources, agricultural production, food, environmental conservation, and ecosystem maintenance. | E22: Agricultural chemistry, production and environmental agriculture, forest and aquatic science, agricultural engineering and economics, environmental assessment and conservation, etc.
B23: Social Sciences | C23: A research area that theoretically and empirically analyzes human behavior, institutions, organizations, markets, policies, and social structures. | E23: Cultural anthropology, legal systems, political science, economics and business administration, sociology, education, psychology, etc.
B24: Arts / Humanities | C24: A research area that explores culture, history, thought, language, expression, and value formation through interpretation, criticism, and historical source analysis. | E24: Philosophy, art studies, literature and linguistics, history, archaeology, etc.
A26: [Reference: Use Case Classification]
B28: Development / Use | C28: Use Case Classification | D28: Definition / Criteria | E28: Specific Examples
B29: Development | C29: Training Dataset Construction | D29: Applicable when the primary activity is data collection or processing intended for future use in AI / deep learning (including data collection through experiments, fieldwork, etc.) | E29: ・Making historical documents "AI-ready" through digitization, preprocessing, and metadata curation ・Preparing training datasets for developing machine learning potentials in chemistry
C30: Adaptation of Existing Models | D30: Applicable when the primary activity is making an existing foundation model more lightweight, faster, or optimized through post-training or fine-tuning (Note: activities such as building RAG without training fall under "Use," not this category) | E30: ・Fine-tuning a foundation model to develop a model that extracts, structures, and organizes semiconductor material information from diverse scientific documents ・Developing a small, cost-effective and easy-to-operate model based on a foundation LLM
C31: AI Model Development | D31: Applicable when all stages of the cycle—data collection, pre-training, fine-tuning, validation, and evaluation—are performed by the researcher themselves (includes not only large language models but also research utilizing deep learning) | E31: ・Developing a small AI model that can schedule and automate biological experiments ・Developing AI simulations for physics systems incorporating fluid equations ・Developing a deep learning model for jet classification in particle acceleration experiments
C32: Evaluation of Existing Models | D32: Applicable to research whose primary purpose is "validation, evaluation, and improvement" of existing models. Research aimed at understanding model mechanisms (e.g., probing) for the purpose of AI improvement also falls under this category. | E32: ・Analyzing attention mechanisms to extract insights for developing AI with fewer hallucinations ・Research aimed at improving the reliability of "LLM-as-a-judge"
B33: Use | C33: Experimental Automation / Autonomization | D33: Applicable when physical laboratory equipment, robots, or machines are connected (Note: if activity during the project period is limited to code development and does not involve actual equipment, select the most appropriate category from the other classifications instead) | E33: ・Developing an AI camera that connects with cameras to detect signs of crop disease ・Developing AI that connects with robotic arms to autonomously carry out small-scale experiments
C34: Simulation / Digital Twin | D34: Applicable to research that primarily uses existing AI (*) and intends to replace processes currently requiring actual experiments or observations with simulations or digital twins (research involving from-scratch model development falls under "AI Model Development") | E34: ・Simulating the process of language acquisition by treating LLMs as humans ・Simulating "society" using AI agents ・Developing a prototype clinical trial using virtual organs
C35: Discovery / Design Support | D35: Applicable when the primary activity uses existing AI (*) to streamline and autonomize pre-experimental processes—from hypothesis generation to experimental planning—before "actual experiments or analyses" | E35: ・Using existing AI to develop a system that proposes research next-step hypotheses and industry-academia collaboration plans based on industry trends ・Using AI to conduct promising material exploration at the pre-experimental stage in materials design
C36: Advanced Data Analysis / Modeling | D36: Broadly applicable to research that primarily uses existing AI (*) to advance data analysis and prediction (excluding those falling under Simulation / Digital Twin) (Note: research in which the researcher themselves build a complete model falls under "AI Model Development") | E36: ・Using AI to analyze social media data in real time and visualize social conditions ・Using AI to estimate parameters needed for a long-term earthquake prediction model
B37: Other | C37: Other | D37: Use cases or research that do not fit into the above categories, such as primarily theoretical research, research close to "Science for AI," or meta-science related to AI, etc. (*Please select from the above categories whenever possible) | E37: ・Analyzing the social impact of introducing AI into scientific research itself ・Theoretically exploring new AI architectures using knowledge from non-equilibrium statistical mechanics
B38: (*) Using existing AI: Refers to using existing models such as ChatGPT via service or API, or using SaaS / AutoML-type services, etc.
A40: [About the Government-Wide Expense Classification Table]
B42: 1. General Provisions (1) The Government-Wide Expense Classification Table (hereinafter referred to as "the Table") is used in common across all competitive research funding programs. The following confirms the interpretation and operation thereof. (2) Each program shall establish its expense category structure based on the Table, clearly indicating the handling of each expense. 2. Setting Expense Categories (1) Each program shall use the category names listed in the Table. (2) Expense types are classified into three categories: "Direct Costs," "Indirect Costs," and "Sub-Contracting / Joint Implementation Costs." (3) "Direct Costs" shall include "Major Categories," which shall further contain "Sub-Categories." (4) The Major Categories of "Direct Costs" are unified into four items: "Equipment and Supplies," "Personnel Costs / Honoraria," "Travel Expenses," and "Other." (5) Sub-Categories are unified as follows: ・Under "Equipment and Supplies": "Equipment and Fixtures" and "Consumable Supplies" ・Under "Personnel Costs / Honoraria": "Personnel Costs" and "Honoraria" ・Under "Travel Expenses": "Travel Expenses" ・Under "Other": "Outsourcing Costs," "Printing and Binding Costs," "Meeting Expenses," "Communication and Transportation Costs," "Utilities," "Other (Miscellaneous Expenses)," and "Consumption Tax Equivalent" (6) Progress reports shall in principle be submitted by Major Category. Where reporting by Sub-Category is required for specific amounts, the relevant funding agency shall specify this in the "Sub-Category Settings / Handling" column. If a Sub-Category is not established, this shall likewise be specified in the same column. 3. Interpreting Expense Categories (1) To standardize the interpretation of each Direct Cost category, Indirect Costs, and Sub-Contracting / Joint Implementation Costs, explanations are included in the Table. (2) Specific expenditure examples common to all programs are included in the Table to enable researchers to use research funds without confusion. 4. Operating the Table Under Each Program (1) Where the nature of a program makes it inappropriate to include certain expenses under the relevant sub-category, or where specific conditions apply, this shall be stated in the "Special Notes" column. (2) The handling of "Equipment and Fixtures," "Consumable Supplies," and "Consumption Tax Equivalent" shall be described by each program in the "Special Notes" column. For contracted projects, their definitions shall be clearly stated in the "Specific Expenditure Examples" column. (3) The adjusted Table shall be made publicly available, for example by posting it on each program's website. (4) In programs primarily allocating funds to companies where accounting practices differ from this Table, the funding agency may set expense categories with reference to this Table.
A44: [Guidelines for Describing Cost Details (API Costs / Computational Resource Costs)]
B46: In this section, please organize and describe the breakdown of costs associated with AI usage by item. If there are multiple purposes or multiple types of GPUs being used, please divide entries by purpose or GPU type. <Content to include for each item: API Costs> For pay-as-you-go API costs, please refer to the examples below. Even for non-pay-as-you-go usage, describe API usage for data retrieval, queries, or integration as appropriate. ■ Processing Target: Describe the data to be processed. (Examples) Literature, experiment logs, images, videos, audio data ■ Amount: Total cost for the relevant purpose (in thousands of yen) ■ Cost Basis: Specific basis for estimating API costs. (Suggested points) Volume and frequency of data processing, re-execution rate, etc. <Content to include for each item: Computational Resource Costs (including Cloud GPU)> ■ GPU Type: Type of computational resource (GPU, etc.) planned for use. (Examples) NVIDIA A100, V100, etc. ■ Reason for Selecting This GPU: Purpose of use and performance requirements, etc. (Suggested points) Required processing speed and type of data to be processed ■ Amount: Total cost for the relevant purpose (in thousands of yen) ■ Cost Basis: Basis for estimating usage fee for computational resources. (Suggested points) Volume and frequency of data processing, etc.

Sheet Reference) Government-Wide Expe
A2: Government-Wide Expense Classification Table
E3: Program / Project Name: Supporting Pioneering Research through AI for 1,000 Discovery challenges（SPReAD）
B5: Major Category | C5: Sub-Category | D5: Specific Expenditure Examples for Sub-Categories | E5: Sub-Category Settings / Handling, etc. | F5: Special Notes
A6: Direct Costs | B6: Equipment and Supplies | C6: Equipment and Fixtures | D6: Costs required for the purchase, manufacture, or installation of machinery, tools, equipment, and other items necessary for the implementation of the project. Includes renovation of equipment (capital expenditures primarily aimed at enhancing functions or increasing durability) and software (integrated into and functioning as part of machinery or equipment). | E6: When acquiring computational resources as physical assets (e.g., purchasing GPU-equipped devices), classify them under "Equipment and Fixtures" and also record them under "Computational Resource Costs (including Cloud GPU)" on Research Plan_Sheet 4. | F6: GPU-equipped servers, workstations, research storage devices, and other similar computing equipment acquired as physical assets that should be managed as fixtures shall be classified under "Equipment and Fixtures."
C7: Consumable Supplies | D7: Costs for purchasing materials, parts, consumables, and other items directly required for project implementation, including examples such as: ・Software (including version upgrades) ・Books and publications (including annual subscription fees) ・PC peripherals, CD-ROMs, DVD-ROMs, etc. ・Laboratory animals, reagents, reagent kits, laboratory instruments ・Prototypes etc. | F7: Inexpensive peripherals, recording media, replacement parts, and other computing equipment acquired as physical assets that should be managed as consumables shall be classified under "Consumable Supplies."
B8: Personnel Costs / Honoraria | C8: Personnel Costs | D8: Personnel costs for researchers who directly engage in and primarily lead the project: ・Personnel costs (including paid leave) of the principal investigator themselves, statutory welfare expenses, commuting allowances, housing allowances, dependent allowances, location allowances, retirement allowances for contracted research, etc. ・Personnel costs (including paid leave) of postdocs and other researchers directly employed by the institution, statutory welfare expenses, commuting allowances, housing allowances, dependent allowances, location allowances, retirement allowances for contracted research, etc. ・Costs for specialized equipment operators and dispatched researchers from staffing agencies ・Costs for researchers seconded from other institutions etc. Personnel costs for those who directly engage in the project in a supporting capacity: ・Research administrators, research assistants ・Part-time workers, temporary staff, and dispatched employees performing research support tasks ・Technical assistants, academic assistants, administrative assistants, secretaries etc. *Personnel costs shall be calculated based on the institution's salary regulations. | F8: Personnel cost expenditures are not eligible under this program.
C9: Honoraria | D9: Costs for providing knowledge, information, and technical expertise necessary for project implementation: ・Honoraria for attendance at research steering committee and other external committee meetings ・Honoraria for lectures and talks ・Honoraria for services utilizing individual specialized skills (lectures, technical guidance, manuscript writing, peer review, proofreading (foreign language, etc.)) ・Honoraria for data and document organization services ・Honoraria for interpretation and translation (commissioned to individuals) ・Work fees for students, etc. ・Honoraria for research subjects etc. *Honoraria shall be calculated based on the institution's honorarium payment regulations.
B10: Travel Expenses | C10: Travel Expenses | D10: The following costs related to travel: ① Costs for domestic and international business trips or travel by researchers and assistants (including undergraduate and graduate students) for project implementation (transportation, accommodation, daily allowances, travel incidentals). Includes transportation, accommodation, daily allowances, and travel incidentals for attending academic conferences. ② Costs for domestic and international business trips or travel by project collaborators (other than ①) for collecting knowledge, information, and opinions necessary for project implementation (transportation, accommodation, daily allowances, travel incidentals) ③ Costs for inviting overseas researchers, etc. (including graduate students) (transportation, accommodation, daily allowances, subsistence expenses, travel incidentals) ④ Costs incurred when researchers travel to or return from their assignment location (transportation, accommodation, daily allowances, relocation costs, dependent relocation costs, travel incidentals) etc. *Travel costs shall be calculated based on the institution's travel regulations. *Cancellation fees for travel are included (only when cancellation fees are permitted due to unavoidable circumstances). *"Travel incidentals" refers to airport usage fees, passport issuance fees, visa fees, vaccination fees, actual departure/arrival taxes, fuel surcharges, aviation insurance fees, airline ticket handling fees, etc.
B11: Other | C11: Outsourcing Costs | D11: The following costs related to outsourcing: Costs for outsourcing maintenance of equipment directly necessary for the project, data analysis, etc.: ・Service contracts for operation, maintenance, and repair of machinery and equipment (including routine legal inspections, periodic inspections, and daily maintenance to preserve functionality and restore original condition of equipment purchased under this project) ・Service contracts for raising laboratory animals, design (designed to applicant's specifications), testing, analysis/inspection, appraisal, material processing, etc. ・Service contracts for interpretation, translation, proofreading (review), surveys, research, etc. (contracted to companies) etc. *Excludes items falling under "Sub-Contracting / Joint Implementation Costs"
C12: Printing and Binding Costs | D12: Costs for printing and binding materials related to the project: ・Printing costs for creating documents necessary for research activities, such as flyers, posters, photographs, and drawing copies etc.
C13: Meeting Expenses | D13: Costs for holding meetings, symposiums, seminars, etc. directly necessary for project implementation: ・Costs for holding research steering committees and other committee meetings ・Venue rental fees ・Interpretation fees for international conferences ・Food and beverage costs for meetings and receptions (excluding alcoholic beverages) etc.
C14: Communication and Transportation Costs | D14: Communication and telephone costs for transporting items and transmitting/receiving data directly necessary for project implementation: ・Telephone and fax charges ・Internet usage fees ・Courier service fees ・Postal fees etc.
C15: Utilities (Electricity, Gas, Water) | D15: Costs for electricity, gas, water, and other utilities required to operate machinery and equipment used for the project.
C16: Other (Miscellaneous Expenses) | D16: Costs directly necessary for project implementation beyond the above categories: ・Costs for renting/leasing/using equipment and other items (rental, lease, rental), storage fees, land and building rental fees, field rental fees ・Usage fees for facilities and equipment within research institutions ・Conference participation fees (including lunch and banquet fees inseparable from conference participation fees; travel costs for attending conferences are classified under "Travel Expenses") ・Cancellation fees for conference participation, etc. (only when permitted due to unavoidable circumstances) ・Research results dissemination costs (manuscript review fees, paper submission fees (publication fees), reprint fees, results report preparation and binding fees, textbook preparation and publishing fees, website creation fees, etc.) ・Public relations costs (websites, newsletters, etc.), advertising and promotion costs, recruitment costs ・Insurance premiums (for those necessary for the project) ・Wire transfer fees ・Data and rights usage fees (patent usage fees, license fees (including software license fees), database usage fees, cloud usage fees, etc.) ・Patent-related costs ・Pharmaceutical consultation fees ・Drug and waste disposal costs ・Microfilming and digitization of books, etc. ・Rental car and taxi fees (excluding those classified under "Travel Expenses" per travel regulations) ・Costs for outsourcing non-research duties (buyout costs) etc. | E16: Costs required for API usage (e.g., pay-as-you-go API fees, fees for AI models and other analytical APIs, fees for APIs used for data retrieval/queries/integration, fees for accessing databases or external platforms via API, etc.) shall be classified under "API Costs" on Research Plan_Sheet 4. Additionally, costs related to procurement/use of computational resources (e.g., commercial cloud service fees, lease/rental fees for GPU-equipped devices, usage fees for HPC or GPU clusters within research institutions, software license fees/subscription fees, etc.) shall be classified under "Computational Resource Costs (including Cloud GPU)" on Research Plan_Sheet 4. | F16: Under Other (Miscellaneous Expenses), expenditures for promoting the development of next-generation human resources in science and technology fields that contribute to the spread and promotion of AI for Science are permitted: ・Costs for online science, physics, chemistry classes and outreach lectures at elementary, junior high, and high schools by doctoral degree holders in science and mathematics fields ・Costs for creating and distributing research results as content easily understandable to junior and senior high school students via social media, etc. Note: Expenditures for "costs for outsourcing non-research duties (buyout costs)" are not eligible under this program.
C17: Consumption Tax Equivalent (Contract Projects Only) | D17: Amounts equivalent to 10% of "personnel costs excluding commuting allowances," "international travel expenses and invitation travel expenses for foreign researchers excluding preparation allowances and domestic travel expenses," "various honoraria," and "insurance premiums," and other amounts that are non-taxable (non-deductible) transactions for consumption tax purposes. | F17: This program is a grant-type program, so this item is not applicable.
A19: Indirect Costs | D19: Costs allocated at a fixed ratio to direct costs and used by the recipient institution for management and other purposes associated with conducting research under competitive research funding.
A21: Sub-Contracting / Joint Implementation Costs | D21: Costs for the contractor to further sub-contract a portion of the contracted work to a third party or to implement it jointly with a third party (including amounts equivalent to indirect costs). | F21: This program is a grant-type program, so this item is not applicable.

Sheet Research Plan_Sheet 1
A1: Form 1 | M1: English | N1: Sheet 1
B2: FY2026 Supporting Pioneering Research through AI for 1,000 Discovery challenges（SPReAD） Research Plan
G6: Submission Date | I6: Year | K6: Month | M6: Day
B7: Applicant Information
B8: e-Rad Researcher ID (8-digit half-width numerals)
C9: If the principal investigator does not have their own researcher ID, please enter the ID of the supervising faculty member or other person submitting on their behalf. *Due to Excel's specifications, a leading "0" may not be displayed, but this will not affect the review process.
B10: Email Address
C11: *Please be sure to use the email address of the principal investigator issued by their affiliated institution.
B12: Principal Investigator Name | C12: Full Name
C14: *Please leave one half-width space between the family name and given name.
B15: Date of Birth (Western calendar, half-width numerals) | E15: Year | G15: Month | I15: Day
B16: e-Rad Institution Code (half-width numerals)
C17: *Please note that this is different from the institution number for Grants-in-Aid for Scientific Research (Kakenhi). If you are unsure, please check on e-Rad or with your affiliated institution.
B18: Institution
B19: Department / Division
B20: Position / Title | H20: Students only: please select "Y" from the dropdown. →
B21: Institution Category
C22: *Please select the most applicable option from the dropdown. *If the dropdown is unavailable, please select from the "Institution Category" column in the "List" tab and copy it here.
B23: Applicant Attribute Category
C24: *Please select the most applicable option from the dropdown. *If the dropdown is unavailable, please select from the "Applicant Attribute Category" column in the "List" tab and copy it here.
B26: Research Project Information
B27: Research Area
C28: *Please refer to the "Notes) Important Notes for Filling Out This Form" tab and select the most applicable option from the dropdown. *If the dropdown is unavailable, please select from column B "Research Area" in the "Reference: Research Area Classification" table in the "Notes) Important Notes for Filling Out This Form" tab and copy it here.
B29: Main Use Case Classification
C30: *Please refer to the "Notes) Important Notes for Filling Out This Form" tab and select the most applicable option from the dropdown. *If the dropdown is unavailable, please select from column C "Use Case Classification" in the "Reference: Use Case Classification" table in the "Notes) Important Notes for Filling Out This Form" tab and copy it here.
B31: If "9. Other" is selected (free text)
B32: Sub-Use Case Selection | D32: 1. Training Dataset Construction | F32: 2. Adaptation of Existing Models | H32: 3. AI Model Development | J32: 4. Evaluation of Existing Models
D33: 5. Experimental Automation / Autonomization | F33: 6. Simulation / Digital Twin | H33: 7. Discovery / Design Support | J33: 8. Advanced Data Analysis / Modeling
C34: *Please refer to the "Notes) Important Notes for Filling Out This Form" tab and mark all items that apply as secondary purposes for achieving the main use case by selecting "Y" from the dropdown. | N34: Character Count
B35: Research Project Title | N35: =IF(C35="",0,LEN(TRIM(C35))-LEN(SUBSTITUTE(TRIM(C35)," ",""))+1) -> 0
C36: (English: around 30 words) *The above character count is a guideline.
B38: AI Utilization Level
B39: AI Utilization Level Selection (multiple selections allowed) | D39: Not using AI at all in research | F39: Using AI for non-research tasks (email, translation, etc.) | H39: Using AI for literature searches or summaries in research | J39: Using AI for writing papers or preparing research presentations | L39: Using AI for hypothesis consideration or idea generation
D40: Have used AI (including self-created deep learning code, etc.) to analyze or process research data | F40: Have presented analysis results using AI or deep learning as research outcomes in papers or presentations | H40: Have integrated existing AI into the research process via API | J40: Have developed AI / deep learning models myself (including the full cycle of training and evaluation) and used them in research | L40: Have experience developing new foundation models
C41: *This does not directly affect acceptance or rejection. *Please mark all applicable items by selecting "Y" from the dropdown. | N41: English
B42: Specific Current Usage Methods | N42: =IF(C42="",0,LEN(TRIM(C42))-LEN(SUBSTITUTE(TRIM(C42)," ",""))+1) -> 0
C43: (English: around 120 words) *The above character count is a guideline.
B45: Research Expenses
B46: Research Expenses (half-width numerals) | C46: Research Expenses (thousand yen) | E46: Breakdown (thousand yen)
E47: Equipment and Fixtures | G47: Consumable Supplies | I47: Honoraria | K47: Travel Expenses | L47: Other
...

Sheet Research Plan_Sheet 2
A1: Form 1 | E1: English | F1: Sheet 2
B2: FY2026 Supporting Pioneering Research through AI for 1,000 Discovery challenges（SPReAD） Research Plan
B3: Important Notes ■ Please be sure to refer to "4. For Applicants (3) Preparation and Submission of Application Documents (Research Plan)" in the Call for Applications before filling in this form. ■ Descriptions should in principle be written in prose. Research plans using colored figures or text will be reviewed as submitted. ■ If figures or tables are needed for explanation, please include them in the designated figure/table section provided later in this form.
B6: # | C6: Item | D6: Input Field | E6: Character Count *An error will be displayed in red if the count is below or above the specified limit.
B8: 1 | C8: Research Objectives Please specifically describe the content and purpose of the research project: what research you will conduct and for what purpose. Clearly state the phenomena and issues to be addressed, the problems to be solved, and the knowledge to be obtained. <Character Count Limit> English: 48–240 words | E8: =IF($D8="",0,LEN(TRIM($D8))-LEN(SUBSTITUTE(TRIM($D8)," ",""))+1) -> 0
B9: 2 | C9: Research Methods Please describe the specific methods for achieving the research objectives. Organize the research process step by step and clearly indicate how AI will be applied or developed at each stage. Also describe as specifically as possible the types of data to be used, how they will be obtained, evaluation metrics, and verification methods. <Character Count Limit> English: 96–480 words | E9: =IF($D9="",0,LEN(TRIM($D9))-LEN(SUBSTITUTE(TRIM($D9)," ",""))+1) -> 0
B10: 3 | C10: Rationale and Feasibility of AI Utilization Please describe the necessity and rationale for utilizing AI in this research project. Specifically explain the limitations of conventional methods and what becomes achievable through AI utilization, clearly conveying the significance of using AI in this research. <Character Count Limit> English: 96–480 words | E10: =IF($D10="",0,LEN(TRIM($D10))-LEN(SUBSTITUTE(TRIM($D10)," ",""))+1) -> 0
B11: 4 | C11: Achievement Goals Please briefly state the ultimate goal this research project aims to achieve, and then describe in concrete terms what you aim to accomplish during the research period of this program (approximately 180 days). The ultimate goal may include objectives to be achieved after the end of the funding period or future research developments. On that basis, please specify how far the research will advance toward that ultimate goal within the research period of this program. In doing so, clearly distinguish the milestones and deliverables to be achieved at the interim stage (after 3 months) and at the end of the funding period (after 6 months), and describe them concretely, including prototypes, proof of concept (PoC), preliminary validation, and other relevant outputs. <Character Count Limit> English: 60–300 words | E11: =IF($D11="",0,LEN(TRIM($D11))-LEN(SUBSTITUTE(TRIM($D11)," ",""))+1) -> 0
B12: 5 | C12: Plan for Extracting and Sharing AI Utilization Know-How This program will build a community for sharing knowledge about AI for Science. Please describe how you will organize and extract the AI utilization knowledge gained through this research and share and disseminate it within that community. Systematically organize the methods and challenges of AI utilization at each stage, and describe with awareness of sharing in a form that can be utilized in other research fields. <Character Count Limit> English: 36–180 words | E12: =IF($D12="",0,LEN(TRIM($D12))-LEN(SUBSTITUTE(TRIM($D12)," ",""))+1) -> 0
B13: 6 | C13: Publication Policy for Research Outcomes (Optional) Please describe what research outcomes you plan to publish and how you plan to publish them. (Examples: papers, research data, source code, prototypes, reports, etc.) <Character Count Limit> English: up to 90 words | E13: =IF($D13="",0,LEN(TRIM($D13))-LEN(SUBSTITUTE(TRIM($D13)," ",""))+1) -> 0
B14: 7 | C14: Research Achievements, etc. If you have major achievements (academic papers, conference presentations, or books) related to this research project, please list up to 5 items total, one per cell, in bullet point format. Please include only achievements that include the principal investigator themselves. ・Academic papers: Include "Title," "Author(s) (underline the applicant)," "Journal Name," and "Publication Date." "Citation count" may be added, but if so, specify the source and retrieval date. ・Conference presentations: Include "Title," "Author(s) (underline the applicant)," "Conference Name," and "Presentation Date." If there were any awards at the conference, this may also be noted. ・Books: Include "Title," "Author(s) (underline the applicant)," "Publisher," and "Publication Date." "Section title" may also be included.
B20: [Reference: Attaching Figures] To facilitate understanding of the research content, please attach figures as appropriate below this point that illustrate the research process, points where AI is applied, etc. Figures should be concise and clear, supplementing relationships and flows that are difficult to convey in text (maximum 1 figure). *There is no need to insert images into cells.

Sheet Research Plan_Sheet 3
A1: Form 1 | N1: English | O1: Sheet 3
B2: FY2026 Supporting Pioneering Research through AI for 1,000 Discovery challenges（SPReAD） Research Plan
B3: Research Expenses and Their Necessity
B4: Important Notes ■ If "Equipment and Fixtures," "Travel Expenses," or "Honoraria" accounts for more than 90% of the research budget, or if any particular item under "Other" (Consumable Supplies, Other) accounts for a disproportionately large share, the necessity of that expense for conducting the research must be stated in the Research Plan. ■ The total fields are calculated automatically. When entering amounts, always use half-width numerals and round down any amount below 1,000 yen. ■ Do not include indirect costs; enter direct costs only. ■ When filling in this form, be sure to refer to the "Notes) Important Notes for Filling Out This Form" tab and the "Reference) Government-Wide Expense Classification Table" tab. ■ If API or computational resource (including cloud GPU) costs are listed under "Other," please provide detailed information in "Research Plan_Sheet 4." ■ If computational resources are acquired as physical assets and classified under "Equipment and Fixtures," please also provide detailed information in "Research Plan_Sheet 4."
B7: 1 | C7: Equipment, Fixtures and Consumable Supplies
C9: Equipment and Fixtures Breakdown | L9: Consumable Supplies Breakdown
C10: # | D10: Item Description | E10: Installing Institution | G10: Unit Price (thousand yen) | I10: Quantity | J10: Amount (thousand yen) | L10: # | M10: Item Description | N10: Amount (thousand yen)
C11: 1 | J11: =G11*I11 -> 0 | L11: 1
C12: 2 | J12: =G12*I12 -> 0 | L12: 2
C13: 3 | J13: =G13*I13 -> 0 | L13: 3
C14: 4 | J14: =G14*I14 -> 0 | L14: 4
C15: 5 | J15: =G15*I15 -> 0 | L15: 5
C16: 6 | J16: =G16*I16 -> 0 | L16: 6
C17: 7 | J17: =G17*I17 -> 0 | L17: 7
C18: 8 | J18: =G18*I18 -> 0 | L18: 8
C19: 9 | J19: =G19*I19 -> 0 | L19: 9
C20: 10 | J20: =G20*I20 -> 0 | L20: 10
C21: 11 | J21: =G21*I21 -> 0 | L21: 11
C22: 12 | J22: =G22*I22 -> 0 | L22: 12
... C30: 20 | J30: =G30*I30 -> 0 | L30: 20
C31: Total | J31: =SUM(J11:J30) -> 0 | L31: Total | N31: =SUM(N11:N30) -> 0
C33: Necessity of Equipment, Fixtures and Consumable Supplies
B36: 2 | C36: Honoraria and Travel Expenses
C38: Honoraria Breakdown | G38: Domestic Travel Expense Breakdown | L38: International Travel Expense Breakdown
C39: # | D39: Item Description | E39: Amount (thousand yen) | G39: # | H39: Item Description | J39: Amount (thousand yen) | L39: # | M39: Item Description | N39: Amount (thousand yen)
C40: 1 | G40: 1 | L40: 1
C41: 2 | G41: 2 | L41: 2
C42: 3 | G42: 3 | L42: 3
C43: 4 | G43: 4 | L43: 4
C44: 5 | G44: 5 | L44: 5
C45: 6 | G45: 6 | L45: 6
C46: 7 | G46: 7 | L46: 7
C47: 8 | G47: 8 | L47: 8
C48: 9 | G48: 9 | L48: 9
C49: 10 | G49: 10 | L49: 10
C50: 11 | G50: 11 | L50: 11
C51: 12 | G51: 12 | L51: 12
... C59: 20 | G59: 20 | L59: 20
C60: Total | E60: =SUM(E40:E59) -> 0 | G60: Total | J60: =SUM(J40:J59) -> 0 | L60: Total | N60: =SUM(N40:N59) -> 0
C62: Necessity of Honoraria and Travel Expenses
...

Sheet Research Plan_Sheet 4
A1: Form 1 | G1: English | H1: Sheet 4
B2: FY2026 Supporting Pioneering Research through AI for 1,000 Discovery challenges（SPReAD） Research Plan
B3: Research Expenses and Their Necessity
B4: Important Notes ■ In this section, please organize and describe the breakdown of costs associated with AI usage by item. If there are multiple purposes or multiple types of GPUs being used, please divide entries by purpose or GPU type.
C7: Cost Details: API Costs
C8: # | D8: Processing Target | E8: Amount (thousand yen) | F8: Cost Basis (input/output volume per request, processing speed, re-execution rate, etc.)
C9: 1
C10: 2
C11: 3
C12: 4
C13: 5
C14: 6
C15: 7
C16: 8
C17: 9
C18: 10
C20: Cost Details: Computational Resource Costs (including Cloud GPU)
C21: # | D21: GPU Type | E21: Reason for Selecting This GPU | F21: Amount (thousand yen) | G21: Cost Basis (volume and frequency of data processing, etc.)
C22: 1
C23: 2
C24: 3
C25: 4
C26: 5
C27: 6
C28: 7
C29: 8
C30: 9
C31: 10

Sheet List
A1: Research Area | B1: Use Case Classification | C1: Institution Category | D1: Applicant Attribute Category
A2: Clinical Science | B2: 1. Training Dataset Construction | C2: University | D2: Faculty Member
A3: Life Sciences / Pharmacy | B3: 2. Adaptation of Existing Models | C3: Technical College (Kosen) | D3: Researcher (including Postdoc)
A4: Chemistry | B4: 3. AI Model Development | C4: Public Research Institution | D4: Doctoral Student
A5: Mechanical / Infrastructure / Energy Engineering | B5: 4. Evaluation of Existing Models | C5: Private Company | D5: Master's Student
A6: Materials / Process / Applied Biomedical Engineering | B6: 5. Experimental Automation / Autonomization | C6: Non-Profit Organization / Public Interest Corporation | D6: Undergraduate Student
A7: Electrical Engineering / Electronic Engineering / Information Science / Computer Science | B7: 6. Simulation / Digital Twin | C7: Other (only if none of the above apply) | D7: Technical / Administrative Staff / URA, etc.
A8: Mathematics / Physics / Earth Sciences | B8: 7. Discovery / Design Support | D8: Engineer / Developer
A9: Agriculture / Environmental Science / Ecology | B9: 8. Advanced Data Analysis / Modeling | D9: Other (only if none of the above apply)
A10: Social Sciences | B10: 9. Other
A11: Arts / Humanities
